<?xml version="1.0"?>
<robot name="my_robot">

    <material name="blue">
        <color rgba="0 0 1 1"/>
    </material>
    
    <material name="red">
        <color rgba="1 0 0 1"/>
    </material>

    <material name="green">
        <color rgba="0 1 0 1"/>
    </material>

    <material name="white">
        <color rgba="1 1 1 1"/>
    </material>

    <link name="base_link">
        <visual>
        <geometry>
            <box size="0.6 0.4 0.2"/>
        </geometry>
        <origin xyz="0 0 0.1" rpy="0 0 0"/>
        <material name="blue"/>
        </visual>
    </link>


    <link name="lidar">
        <visual>
            <geometry>
                <cylinder radius="0.1" length="0.2"/>
            </geometry>
            <origin xyz="0 0 0" rpy="0 0 0"/>
            <material name="white"/>
        </visual>
    </link>


    <link name="wheel_left">
        <visual>
            <geometry>
                <cylinder radius="0.05" length="0.02"/>
            </geometry>
            <origin xyz="0 0 0" rpy="1.5708 0 0"/>
            <material name="red"/>
        </visual>
    </link>

    <link name="wheel_right">
        <visual>
            <geometry>
                <cylinder radius="0.05" length="0.02"/>
            </geometry>
            <origin xyz="0 0 0" rpy="1.5708 0 0"/>
            <material name="red"/>
        </visual>
    </link>

   <link name="caster_wheel">
        <visual>
            <geometry>
                <sphere radius="0.05"/>
                </geometry>
            <origin xyz="0 0 0" rpy="0 0 0"/>
            <material name="green"/>
        </visual>
    </link>

    <joint name="lidar_joint" type="fixed">
        <parent link="base_link"/>
        <child link="lidar"/>
        <origin xyz="0 0 0.2" rpy="0 0 0"/>
    </joint>

    <joint name="wheel_left_joint" type="continuous">
        <parent link="base_link"/>
        <child link="wheel_left"/>
        <origin xyz="-0.2 0.15 0" rpy="0 0 0"/>
        <axis xyz="0 1 0"/>
    </joint>

    <joint name="wheel_right_joint" type="continuous">
        <parent link="base_link"/>
        <child link="wheel_right"/>
        <origin xyz="0.2 0.15 0" rpy="0 0 0"/>
        <axis xyz="0 1 0"/>
    </joint>

    <joint name="caster_wheel_joint" type="continuous">
        <parent link="base_link"/>
        <child link="caster_wheel"/>
        <origin xyz="0 -0.15 0" rpy="0 0 0"/>
        <axis xyz="0 1 0"/>
    </joint>

</robot>  
